Workbook

Sheet AOP Summary
C2: Zone | D2: ZH | F2: AOP 2026-27 OVERALL STATUS | K2: APR 25 | O2: OCT 25 | V2: NOV 25 | AD2: DEC 25 | AM2: JAN 26 | AU2: FEB 26 | BD2: MAR 26 | BJ2: APRIL 26 | BP2: MAY 26 | BV2: JUNE 26 | CB2: JULY 26 | CH2: AUGUST 26
F4: Planned | G4: Actual | H4: WIP | I4: YTS | K4: March 25 Carry Forward | L4: APR 25 Planned | M4: APR 25 Actual | O4: AUG 25 Carry Forward | P4: SEP 25 Carry Forward | Q4: Oct 25 Planned | R4: Oct 25 Actual | S4: TOTAL Oct 25 Actual | T4: WIP | V4: AUG 25 Carry Forward | W4: SEP 25 Carry Forward | X4: OCT 25 Carry Forward | Y4: NOV 25 Planned | Z4: NOV 25 Actual | AA4: TOTAL NOV 25 Actual | AB4: WIP | AD4: AUG 25 Carry Forward | AE4: SEP 25 Carry Forward | AF4: OCT 25 Carry Forward | AG4: NOV 25 Carry Forward | AH4: DEC 25 Planned | AI4: DEC 25 Actual | AJ4: TOTAL DEC 25 Actual | AK4: WIP | AM4: OCT 25 Carry Forward | AN4: NOV 25 Carry Forward | AO4: DEC 25 Carry Forward | AP4: JAN 26 Planned | AQ4: JAN 26 Actual | AR4: TOTAL JAN 26 Actual | AS4: WIP | AU4: NOV 25 Carry Forward | AV4: DEC 25 Carry Forward | AW4: JAN 26 Carry Forward | AX4: FEB 26 Planned | AY4: FEB 26 Actual | AZ4: TOTAL FEB 26 Actual | BA4: WIP | BD4: MAR 26 Planned | BE4: TOTAL MAR 26 Actual | BF4: WIP | BG4: YTS | BH4: TOTAL MAR 26 Actual | BJ4: APRIL 26 Planned | BK4: APR 26 Actual | BL4: WIP | BM4: YTS | BN4: TOTAL APR 26 Actual | BP4: MAY 26 Planned | BQ4: MAY 26 Actual | BR4: WIP | BS4: YTS | BT4: TOTAL MAY 26 Actual | BV4: JUNE 26 Planned | BW4: JUNE 26 Actual | BX4: WIP | BY4: YTS | BZ4: TOTAL JUNE 26 Actual | CB4: JULY 26 Planned | CC4: JULY 26 Actual | CD4: WIP | CE4: YTS | CF4: TOTAL JULY 26 Actual | CH4: AUGUST 26 Planned | CI4: AUGUST 26 Actual | CJ4: WIP | CK4: YTS | CL4: TOTAL JULY 26 Actual
K5: Actual | O5: Actual | P5: Actual | V5: Actual | W5: Actual | X5: Actual | AD5: Actual | AE5: Actual | AF5: Actual | AG5: Actual | AM5: Actual | AN5: Actual | AO5: Actual | AU5: Actual | AV5: Actual | AW5: Actual
C6: NORTH WEST | D6: RT | F6: =SUM(L6,Q6,Y6,AH6,AP6,AX6,BD6,BJ6,BP6) -> 77 | G6: =SUM(S6,AA6,AJ6,AR6,AZ6,BH6,BN6,BT6,BZ6) -> 70 | H6: =SUM(T6,AB6,AK6,AS6,BA6,BF6,BL6,BR6,BX6,CD6,CJ6) -> 30 | I6: =SUM(BG6,BM6,BS6,BY6,CE6,CK6) -> 0 | K6: =COUNTIFS(MASTER[ZH],$D6,MASTER[Planned (Month) Bucket],"March 25 PLANNED",MASTER[Actual (Month) Bucket],"April 25") -> 0 | L6: =COUNTIFS(MASTER[ZH],$D6,MASTER[Planned (Month) Bucket],"April 25 PLANNED") -> 0 | M6: =COUNTIFS(MASTER[ZH],$D6,MASTER[Planned (Month) Bucket],"April 25 PLANNED",MASTER[Actual (Month) Bucket],"April 25") -> 0 | O6: =COUNTIFS(MASTER[ZH],$D6,MASTER[Planned (Month) Bucket],"AUGUST 25 PLANNED",MASTER[Actual (Month) Bucket],"OCTOBER 25") -> 0 | P6: =COUNTIFS(MASTER[ZH],$D6,MASTER[Planned (Month) Bucket],"SEPTEMBER 25 PLANNED",MASTER[Actual (Month) Bucket],"OCTOBER 25") -> 0 | Q6: =COUNTIFS(MASTER[ZH],$D6,MASTER[Planned (Month) Bucket],"OCTOBER 25 PLANNED") -> 0 | R6: =COUNTIFS(MASTER[ZH],$D6,MASTER[Planned (Month) Bucket],"OCTOBER 25 PLANNED",MASTER[Actual (Month) Bucket],"OCTOBER 25") -> 0 | S6: =O6+P6+R6 -> 0 | T6: =COUNTIFS(MASTER[EPC Status (Current Week)],T$4,MASTER[ZH],$D6,MASTER[Planned (Month) Bucket],"OCTOBER 25 PLANNED") -> 0 | V6: =COUNTIFS(MASTER[ZH],$D6,MASTER[Planned (Month) Bucket],"AUGUST 25 PLANNED",MASTER[Actual (Month) Bucket],"NOVEMBER 25") -> 0 | W6: =COUNTIFS(MASTER[ZH],$D6,MASTER[Planned (Month) Bucket],"SEPTEMBER 25 PLANNED",MASTER[Actual (Month) Bucket],"NOVEMBER 25") -> 0 | X6: =COUNTIFS(MASTER[ZH],$D6,MASTER[Planned (Month) Bucket],"OCTOBER 25 PLANNED",MASTER[Actual (Month) Bucket],"NOVEMBER 25") -> 0 | Y6: =COUNTIFS(MASTER[ZH],$D6,MASTER[Planned (Month) Bucket],"NOVEMBER 25 PLANNED") -> 0 | Z6: =COUNTIFS(MASTER[ZH],$D6,MASTER[Planned (Month) Bucket],"NOVEMBER 25 PLANNED",MASTER[Actual (Month) Bucket],"NOVEMBER 25") -> 0 | AA6: =V6+W6+X6+Z6 -> 0 | AB6: =COUNTIFS(MASTER[EPC Status (Current Week)],AB$4,MASTER[ZH],$D6,MASTER[Planned (Month) Bucket],"NOVEMBER 25 PLANNED") -> 0 | AD6: =COUNTIFS(MASTER[ZH],$D6,MASTER[Planned (Month) Bucket],"AUGUST 25 PLANNED",MASTER[Actual (Month) Bucket],"DECEMBER 25") -> 0 | AE6: =COUNTIFS(MASTER[ZH],$D6,MASTER[Planned (Month) Bucket],"SEPTEMBER 25 PLANNED",MASTER[Actual (Month) Bucket],"DECEMBER 25") -> 0 | AF6: =COUNTIFS(MASTER[ZH],$D6,MASTER[Planned (Month) Bucket],"OCTOBER 25 PLANNED",MASTER[Actual (Month) Bucket],"DECEMBER 25") -> 0 | AG6: =COUNTIFS(MASTER[ZH],$D6,MASTER[Planned (Month) Bucket],"NOVEMBER 25 PLANNED",MASTER[Actual (Month) Bucket],"DECEMBER 25") -> 0 | AH6: =COUNTIFS(MASTER[ZH],$D6,MASTER[Planned (Month) Bucket],"DECEMBER 25 PLANNED") -> 0 | AI6: =COUNTIFS(MASTER[ZH],$D6,MASTER[Planned (Month) Bucket],"DECEMBER 25 PLANNED",MASTER[Actual (Month) Bucket],"DECEMBER 25") -> 0 | AJ6: =SUM(AD6,AE6,AF6,AG6,AI6) -> 0 | AK6: =COUNTIFS(MASTER[EPC Status (Current Week)],AK$4,MASTER[ZH],$D6,MASTER[Planned (Month) Bucket],"DECEMBER 25 PLANNED") -> 0 | AM6: =COUNTIFS(MASTER[ZH],$D6,MASTER[Planned (Month) Bucket],"OCTOBER 25 PLANNED",MASTER[Actual (Month) Bucket],"JANUARY 26") -> 0 | AN6: =COUNTIFS(MASTER[ZH],$D6,MASTER[Planned (Month) Bucket],"NOVEMBER 25 PLANNED",MASTER[Actual (Month) Bucket],"JANUARY 26") -> 0 | AO6: =COUNTIFS(MASTER[ZH],$D6,MASTER[Planned (Month) Bucket],"DECEMBER 25 PLANNED",MASTER[Actual (Month) Bucket],"JANUARY 26") -> 0 | AP6: =COUNTIFS(MASTER[ZH],$D6,MASTER[Planned (Month) Bucket],"JANUARY 26 PLANNED") -> 1 | AQ6: =COUNTIFS(MASTER[ZH],$D6,MASTER[Planned (Month) Bucket],"JANUARY 26 PLANNED",MASTER[Actual (Month) Bucket],"JANUARY 26") -> 0 | AR6: =SUM(AM6,AN6,AO6,AQ6) -> 0 | AS6: =COUNTIFS(MASTER[EPC Status (Current Week)],AS$4,MASTER[ZH],$D6,MASTER[Planned (Month) Bucket],"JANUARY 26 PLANNED") -> 0 | AU6: =COUNTIFS(MASTER[ZH],$D6,MASTER[Planned (Month) Bucket],"NOVEMBER 25 PLANNED",MASTER[Actual (Month) Bucket],"FEBRUARY 26") -> 0 | AV6: =COUNTIFS(MASTER[ZH],$D6,MASTER[Planned (Month) Bucket],"DECEMBER 25 PLANNED",MASTER[Actual (Month) Bucket],"FEBRUARY 26") -> 0 | AW6: =COUNTIFS(MASTER[ZH],$D6,MASTER[Planned (Month) Bucket],"JANUARY 26 PLANNED",MASTER[Actual (Month) Bucket],"FEBRUARY 26") -> 0 | AX6: =COUNTIFS(MASTER[ZH],$D6,MASTER[Planned (Month) Bucket],"FEBRUARY 26 PLANNED") -> 1 | AY6: =COUNTIFS(MASTER[ZH],$D6,MASTER[Planned (Month) Bucket],"FEBRUARY 26 PLANNED",MASTER[Actual (Month) Bucket],"FEBRUARY 26") -> 0 | AZ6: =SUM(AU6,AV6,AW6,AY6) -> 0 | BA6: =COUNTIFS(MASTER[EPC Status (Current Week)],BA$4,MASTER[ZH],$D6,MASTER[Planned (Month) Bucket],"FEBRUARY 26 PLANNED") -> 0 | BD6: =COUNTIFS(MASTER[ZH],$D6,MASTER[Planned (Month) Bucket],"MARCH 26 PLANNED") -> 33 | BE6: =COUNTIFS(MASTER[ZH],$D6,MASTER[Planned (Month) Bucket],"MARCH 26 PLANNED",MASTER[Actual (Month) Bucket],"MARCH 26")+COUNTIFS(MASTER[ZH],$D6,MASTER[Planned (Month) Bucket],"FEBRUARY 26 PLANNED",MASTER[Actual (Month) Bucket],"MARCH 26")+COUNTIFS(MASTER[ZH],$D6,MASTER[Planned (Month) Bucket],"DECEMBER 25 PLANNED",MASTER[Actual (Month) Bucket],"MARCH 26") -> 0 | BF6: =COUNTIFS(MASTER[EPC Status (Current Week)],BF$4,MASTER[ZH],$D6,MASTER[Planned (Month) Bucket],"MARCH 26 PLANNED") -> 1 | BG6: =COUNTIFS(MASTER[EPC Status (Current Week)],BG$4,MASTER[ZH],$D6,MASTER[Planned (Month) Bucket],"MARCH 26 PLANNED") -> 0 | BH6: =BE6 -> 0 | BJ6: =COUNTIFS(MASTER[ZH],$D6,MASTER[Planned (Month) Bucket],"APRIL 26 PLANNED") -> 8 | BK6: =COUNTIFS(MASTER[ZH],$D6,MASTER[Planned (Month) Bucket],"APRIL 26 PLANNED",MASTER[Actual (Month) Bucket],"APRIL 26")+COUNTIFS(MASTER[ZH],$D6,MASTER[Planned (Month) Bucket],"MARCH 26 PLANNED",MASTER[Actual (Month) Bucket],"APRIL 26")+COUNTIFS(MASTER[ZH],$D6,MASTER[Planned (Month) Bucket],"FEBRUARY 26 PLANNED",MASTER[Actual (Month) Bucket],"APRIL 26")+COUNTIFS(MASTER[ZH],$D6,MASTER[Planned (Month) Bucket],"JANUARY 26 PLANNED",MASTER[Actual (Month) Bucket],"APRIL 26")+COUNTIFS(MASTER[ZH],$D6,MASTER[Planned (Month) Bucket],"MAY 26 PLANNED",MASTER[Actual (Month) Bucket],"APRIL 26") -> 33 | BL6: =COUNTIFS(MASTER[EPC Status (Current Week)],BL$4,MASTER[ZH],$D6,MASTER[Planned (Month) Bucket],"APRIL 26 PLANNED") -> 2 | BM6: =COUNTIFS(MASTER[EPC Status (Current Week)],BM$4,MASTER[ZH],$D6,MASTER[Planned (Month) Bucket],"APRIL 26 PLANNED") -> 0 | BN6: =BK6 -> 33 | BP6: =COUNTIFS(MASTER[ZH],$D6,MASTER[Planned (Month) Bucket],"MAY 26 PLANNED") -> 34 | BQ6: =COUNTIFS(MASTER[ZH],$D6,MASTER[Planned (Month) Bucket],"NOVEMBER 25 PLANNED",MASTER[Actual (Month) Bucket],"MAY 26")+COUNTIFS(MASTER[ZH],$D6,MASTER[Planned (Month) Bucket],"DECEMBER 25 PLANNED",MASTER[Actual (Month) Bucket],"MAY 26")+COUNTIFS(MASTER[ZH],$D6,MASTER[Planned (Month) Bucket],"FEBRUARY 26 PLANNED",MASTER[Actual (Month) Bucket],"MAY 26")+COUNTIFS(MASTER[ZH],$D6,MASTER[Planned (Month) Bucket],"MARCH 26 PLANNED",MASTER[Actual (Month) Bucket],"MAY 26")+COUNTIFS(MASTER[ZH],$D6,MASTER[Planned (Month) Bucket],"APRIL 26 PLANNED",MASTER[Actual (Month) Bucket],"MAY 26")+COUNTIFS(MASTER[ZH],$D6,MASTER[Planned (Month) Bucket],"MAY 26 PLANNED",MASTER[Actual (Month) Bucket],"MAY 26") -> 35 | BR6: =COUNTIFS(MASTER[EPC Status (Current Week)],BR$4,MASTER[ZH],$D6,MASTER[Planned (Month) Bucket],"MAY 26 PLANNED") -> 4 | BS6: =COUNTIFS(MASTER[EPC Status (Current Week)],BS$4,MASTER[ZH],$D6,MASTER[Planned (Month) Bucket],"MAY 26 PLANNED") -> 0 | BT6: =BQ6 -> 35 | BV6: =COUNTIFS(MASTER[ZH],$D6,MASTER[Planned (Month) Bucket],"JUNE 26 PLANNED") -> 19 | BW6: =COUNTIFS(MASTER[ZH],$D6,MASTER[Planned (Month) Bucket],"JUNE 26 PLANNED",MASTER[Actual (Month) Bucket],"JUNE 26")+COUNTIFS(MASTER[ZH],$D6,MASTER[Planned (Month) Bucket],"MAY 26 PLANNED",MASTER[Actual (Month) Bucket],"JUNE 26")+COUNTIFS(MASTER[ZH],$D6,MASTER[Planned (Month) Bucket],"APRIL 26 PLANNED",MASTER[Actual (Month) Bucket],"JUNE 26")+COUNTIFS(MASTER[ZH],$D6,MASTER[Planned (Month) Bucket],"MARCH 26 PLANNED",MASTER[Actual (Month) Bucket],"JUNE 26")+COUNTIFS(MASTER[ZH],$D6,MASTER[Planned (Month) Bucket],"FEBRUARY 26 PLANNED",MASTER[Actual (Month) Bucket],"JUNE 26") -> 2 | BX6: =COUNTIFS(MASTER[EPC Status (Current Week)],BX$4,MASTER[ZH],$D6,MASTER[Planned (Month) Bucket],"JUNE 26 PLANNED") -> 19 | BY6: =COUNTIFS(MASTER[EPC Status (Current Week)],BY$4,MASTER[ZH],$D6,MASTER[Planned (Month) Bucket],"JUNE 26 PLANNED") -> 0 | BZ6: =BW6 -> 2 | CB6: =COUNTIFS(MASTER[ZH],$D6,MASTER[Planned (Month) Bucket],"JULY 26 PLANNED") -> 4 | CC6: =COUNTIFS(MASTER[ZH],$D6,MASTER[Planned (Month) Bucket],"JULY 26 PLANNED",MASTER[Actual (Month) Bucket],"JULY 26") -> 0 | CD6: =COUNTIFS(MASTER[EPC Status (Current Week)],CD$4,MASTER[ZH],$D6,MASTER[Planned (Month) Bucket],"JULY 26 PLANNED") -> 4 | CE6: =COUNTIFS(MASTER[EPC Status (Current Week)],CE$4,MASTER[ZH],$D6,MASTER[Planned (Month) Bucket],"JULY 26 PLANNED") -> 0 | CF6: =CC6 -> 0 | CH6: =COUNTIFS(MASTER[ZH],$D6,MASTER[Planned (Month) Bucket],"AUGUST 26 PLANNED") -> 0 | CI6: =COUNTIFS(MASTER[ZH],$D6,MASTER[Planned (Month) Bucket],"AUGUST 26 PLANNED",MASTER[Actual (Month) Bucket],"AUG 26") -> 0 | CJ6: =COUNTIFS(MASTER[EPC Status (Current Week)],CJ$4,MASTER[ZH],$D6,MASTER[Planned (Month) Bucket],"AUGUST 26 PLANNED") -> 0 | CK6: =COUNTIFS(MASTER[EPC Status (Current Week)],CK$4,MASTER[ZH],$D6,MASTER[Planned (Month) Bucket],"AUGUST 26 PLANNED") -> 0 | CL6: =CI6 -> 0
D7: BK | F7: =SUM(L7,Q7,Y7,AH7,AP7,AX7,BD7,BJ7,BP7) -> 48 | G7: =SUM(S7,AA7,AJ7,AR7,AZ7,BH7,BN7,BT7,BZ7) -> 37 | H7: =SUM(T7,AB7,AK7,AS7,BA7,BF7,BL7,BR7,BX7,CD7,CJ7) -> 27 | I7: =SUM(BG7,BM7,BS7,BY7,CE7,CK7) -> 0 | K7: =COUNTIFS(MASTER[ZH],$D7,MASTER[Planned (Month) Bucket],"March 25 PLANNED",MASTER[Actual (Month) Bucket],"April 25") -> 0 | L7: =COUNTIFS(MASTER[ZH],$D7,MASTER[Planned (Month) Bucket],"April 25 PLANNED") -> 0 | M7: =COUNTIFS(MASTER[ZH],$D7,MASTER[Planned (Month) Bucket],"April 25 PLANNED",MASTER[Actual (Month) Bucket],"April 25") -> 0 | O7: =COUNTIFS(MASTER[ZH],$D7,MASTER[Planned (Month) Bucket],"AUGUST 25 PLANNED",MASTER[Actual (Month) Bucket],"OCTOBER 25") -> 0 | P7: =COUNTIFS(MASTER[ZH],$D7,MASTER[Planned (Month) Bucket],"SEPTEMBER 25 PLANNED",MASTER[Actual (Month) Bucket],"OCTOBER 25") -> 0 | Q7: =COUNTIFS(MASTER[ZH],$D7,MASTER[Planned (Month) Bucket],"OCTOBER 25 PLANNED") -> 0 | R7: =COUNTIFS(MASTER[ZH],$D7,MASTER[Planned (Month) Bucket],"OCTOBER 25 PLANNED",MASTER[Actual (Month) Bucket],"OCTOBER 25") -> 0 | S7: =O7+P7+R7 -> 0 | T7: =COUNTIFS(MASTER[EPC Status (Current Week)],T$4,MASTER[ZH],$D7,MASTER[Planned (Month) Bucket],"OCTOBER 25 PLANNED") -> 0 | V7: =COUNTIFS(MASTER[ZH],$D7,MASTER[Planned (Month) Bucket],"AUGUST 25 PLANNED",MASTER[Actual (Month) Bucket],"NOVEMBER 25") -> 0 | W7: =COUNTIFS(MASTER[ZH],$D7,MASTER[Planned (Month) Bucket],"SEPTEMBER 25 PLANNED",MASTER[Actual (Month) Bucket],"NOVEMBER 25") -> 0 | X7: =COUNTIFS(MASTER[ZH],$D7,MASTER[Planned (Month) Bucket],"OCTOBER 25 PLANNED",MASTER[Actual (Month) Bucket],"NOVEMBER 25") -> 0 | Y7: =COUNTIFS(MASTER[ZH],$D7,MASTER[Planned (Month) Bucket],"NOVEMBER 25 PLANNED") -> 0 | Z7: =COUNTIFS(MASTER[ZH],$D7,MASTER[Planned (Month) Bucket],"NOVEMBER 25 PLANNED",MASTER[Actual (Month) Bucket],"NOVEMBER 25") -> 0 | AA7: =V7+W7+X7+Z7 -> 0 | AB7: =COUNTIFS(MASTER[EPC Status (Current Week)],AB$4,MASTER[ZH],$D7,MASTER[Planned (Month) Bucket],"NOVEMBER 25 PLANNED") -> 0 | AD7: =COUNTIFS(MASTER[ZH],$D7,MASTER[Planned (Month) Bucket],"AUGUST 25 PLANNED",MASTER[Actual (Month) Bucket],"DECEMBER 25") -> 0 | AE7: =COUNTIFS(MASTER[ZH],$D7,MASTER[Planned (Month) Bucket],"SEPTEMBER 25 PLANNED",MASTER[Actual (Month) Bucket],"DECEMBER 25") -> 0 | AF7: =COUNTIFS(MASTER[ZH],$D7,MASTER[Planned (Month) Bucket],"OCTOBER 25 PLANNED",MASTER[Actual (Month) Bucket],"DECEMBER 25") -> 0 | AG7: =COUNTIFS(MASTER[ZH],$D7,MASTER[Planned (Month) Bucket],"NOVEMBER 25 PLANNED",MASTER[Actual (Month) Bucket],"DECEMBER 25") -> 0 | AH7: =COUNTIFS(MASTER[ZH],$D7,MASTER[Planned (Month) Bucket],"DECEMBER 25 PLANNED") -> 0 | AI7: =COUNTIFS(MASTER[ZH],$D7,MASTER[Planned (Month) Bucket],"DECEMBER 25 PLANNED",MASTER[Actual (Month) Bucket],"DECEMBER 25") -> 0 | AJ7: =SUM(AD7,AE7,AF7,AG7,AI7) -> 0 | AK7: =COUNTIFS(MASTER[EPC Status (Current Week)],AK$4,MASTER[ZH],$D7,MASTER[Planned (Month) Bucket],"DECEMBER 25 PLANNED") -> 0 | AM7: =COUNTIFS(MASTER[ZH],$D7,MASTER[Planned (Month) Bucket],"OCTOBER 25 PLANNED",MASTER[Actual (Month) Bucket],"JANUARY 26") -> 0 | AN7: =COUNTIFS(MASTER[ZH],$D7,MASTER[Planned (Month) Bucket],"NOVEMBER 25 PLANNED",MASTER[Actual (Month) Bucket],"JANUARY 26") -> 0 | AO7: =COUNTIFS(MASTER[ZH],$D7,MASTER[Planned (Month) Bucket],"DECEMBER 25 PLANNED",MASTER[Actual (Month) Bucket],"JANUARY 26") -> 0 | AP7: =COUNTIFS(MASTER[ZH],$D7,MASTER[Planned (Month) Bucket],"JANUARY 26 PLANNED") -> 0 | AQ7: =COUNTIFS(MASTER[ZH],$D7,MASTER[Planned (Month) Bucket],"JANUARY 26 PLANNED",MASTER[Actual (Month) Bucket],"JANUARY 26") -> 0 | AR7: =SUM(AM7,AN7,AO7,AQ7) -> 0 | AS7: =COUNTIFS(MASTER[EPC Status (Current Week)],AS$4,MASTER[ZH],$D7,MASTER[Planned (Month) Bucket],"JANUARY 26 PLANNED") -> 0 | AU7: =COUNTIFS(MASTER[ZH],$D7,MASTER[Planned (Month) Bucket],"NOVEMBER 25 PLANNED",MASTER[Actual (Month) Bucket],"FEBRUARY 26") -> 0 | AV7: =COUNTIFS(MASTER[ZH],$D7,MASTER[Planned (Month) Bucket],"DECEMBER 25 PLANNED",MASTER[Actual (Month) Bucket],"FEBRUARY 26") -> 0 | AW7: =COUNTIFS(MASTER[ZH],$D7,MASTER[Planned (Month) Bucket],"JANUARY 26 PLANNED",MASTER[Actual (Month) Bucket],"FEBRUARY 26") -> 0 | AX7: =COUNTIFS(MASTER[ZH],$D7,MASTER[Planned (Month) Bucket],"FEBRUARY 26 PLANNED") -> 0 | AY7: =COUNTIFS(MASTER[ZH],$D7,MASTER[Planned (Month) Bucket],"FEBRUARY 26 PLANNED",MASTER[Actual (Month) Bucket],"FEBRUARY 26") -> 0 | AZ7: =SUM(AU7,AV7,AW7,AY7) -> 0 | BA7: =COUNTIFS(MASTER[EPC Status (Current Week)],BA$4,MASTER[ZH],$D7,MASTER[Planned (Month) Bucket],"FEBRUARY 26 PLANNED") -> 0 | BD7: =COUNTIFS(MASTER[ZH],$D7,MASTER[Planned (Month) Bucket],"MARCH 26 PLANNED") -> 12 | BE7: =COUNTIFS(MASTER[ZH],$D7,MASTER[Planned (Month) Bucket],"MARCH 26 PLANNED",MASTER[Actual (Month) Bucket],"MARCH 26")+COUNTIFS(MASTER[ZH],$D7,MASTER[Planned (Month) Bucket],"FEBRUARY 26 PLANNED",MASTER[Actual (Month) Bucket],"MARCH 26")+COUNTIFS(MASTER[ZH],$D7,MASTER[Planned (Month) Bucket],"JANUARY 26 PLANNED",MASTER[Actual (Month) Bucket],"MARCH 26") -> 0 | BF7: =COUNTIFS(MASTER[EPC Status (Current Week)],BF$4,MASTER[ZH],$D7,MASTER[Planned (Month) Bucket],"MARCH 26 PLANNED") -> 0 | BG7: =COUNTIFS(MASTER[EPC Status (Current Week)],BG$4,MASTER[ZH],$D7,MASTER[Planned (Month) Bucket],"MARCH 26 PLANNED") -> 0 | BH7: =BE7 -> 0 | BJ7: =COUNTIFS(MASTER[ZH],$D7,MASTER[Planned (Month) Bucket],"APRIL 26 PLANNED") -> 12 | BK7: =COUNTIFS(MASTER[ZH],$D7,MASTER[Planned (Month) Bucket],"APRIL 26 PLANNED",MASTER[Actual (Month) Bucket],"APRIL 26")+COUNTIFS(MASTER[ZH],$D7,MASTER[Planned (Month) Bucket],"MARCH 26 PLANNED",MASTER[Actual (Month) Bucket],"APRIL 26")+COUNTIFS(MASTER[ZH],$D7,MASTER[Planned (Month) Bucket],"FEBRUARY 26 PLANNED",MASTER[Actual (Month) Bucket],"APRIL 26")+COUNTIFS(MASTER[ZH],$D7,MASTER[Planned (Month) Bucket],"JANUARY 26 PLANNED",MASTER[Actual (Month) Bucket],"APRIL 26")+COUNTIFS(MASTER[ZH],$D7,MASTER[Planned (Month) Bucket],"MAY 26 PLANNED",MASTER[Actual (Month) Bucket],"APRIL 26") -> 16 | BL7: =COUNTIFS(MASTER[EPC Status (Current Week)],BL$4,MASTER[ZH],$D7,MASTER[Planned (Month) Bucket],"APRIL 26 PLANNED") -> 1 | BM7: =COUNTIFS(MASTER[EPC Status (Current Week)],BM$4,MASTER[ZH],$D7,MASTER[Planned (Month) Bucket],"APRIL 26 PLANNED") -> 0 | BN7: =BK7 -> 16 | BP7: =COUNTIFS(MASTER[ZH],$D7,MASTER[Planned (Month) Bucket],"MAY 26 PLANNED") -> 24 | BQ7: =COUNTIFS(MASTER[ZH],$D7,MASTER[Planned (Month) Bucket],"NOVEMBER 25 PLANNED",MASTER[Actual (Month) Bucket],"MAY 26")+COUNTIFS(MASTER[ZH],$D7,MASTER[Planned (Month) Bucket],"DECEMBER 25 PLANNED",MASTER[Actual (Month) Bucket],"MAY 26")+COUNTIFS(MASTER[ZH],$D7,MASTER[Planned (Month) Bucket],"FEBRUARY 26 PLANNED",MASTER[Actual (Month) Bucket],"MAY 26")+COUNTIFS(MASTER[ZH],$D7,MASTER[Planned (Month) Bucket],"MARCH 26 PLANNED",MASTER[Actual (Month) Bucket],"MAY 26")+COUNTIFS(MASTER[ZH],$D7,MASTER[Planned (Month) Bucket],"APRIL 26 PLANNED",MASTER[Actual (Month) Bucket],"MAY 26")+COUNTIFS(MASTER[ZH],$D7,MASTER[Planned (Month) Bucket],"MAY 26 PLANNED",MASTER[Actual (Month) Bucket],"MAY 26") -> 20 | BR7: =COUNTIFS(MASTER[EPC Status (Current Week)],BR$4,MASTER[ZH],$D7,MASTER[Planned (Month) Bucket],"MAY 26 PLANNED") -> 10 | BS7: =COUNTIFS(MASTER[EPC Status (Current Week)],BS$4,MASTER[ZH],$D7,MASTER[Planned (Month) Bucket],"MAY 26 PLANNED") -> 0 | BT7: =BQ7 -> 20 | BV7: =COUNTIFS(MASTER[ZH],$D7,MASTER[Planned (Month) Bucket],"JUNE 26 PLANNED") -> 13 | BW7: =COUNTIFS(MASTER[ZH],$D7,MASTER[Planned (Month) Bucket],"JUNE 26 PLANNED",MASTER[Actual (Month) Bucket],"JUNE 26")+COUNTIFS(MASTER[ZH],$D7,MASTER[Planned (Month) Bucket],"MAY 26 PLANNED",MASTER[Actual (Month) Bucket],"JUNE 26")+COUNTIFS(MASTER[ZH],$D7,MASTER[Planned (Month) Bucket],"APRIL 26 PLANNED",MASTER[Actual (Month) Bucket],"JUNE 26")+COUNTIFS(MASTER[ZH],$D7,MASTER[Planned (Month) Bucket],"MARCH 26 PLANNED",MASTER[Actual (Month) Bucket],"JUNE 26")+COUNTIFS(MASTER[ZH],$D7,MASTER[Planned (Month) Bucket],"FEBRUARY 26 PLANNED",MASTER[Actual (Month) Bucket],"JUNE 26") -> 1 | BX7: =COUNTIFS(MASTER[EPC Status (Current Week)],BX$4,MASTER[ZH],$D7,MASTER[Planned (Month) Bucket],"JUNE 26 PLANNED") -> 13 | BY7: =COUNTIFS(MASTER[EPC Status (Current Week)],BY$4,MASTER[ZH],$D7,MASTER[Planned (Month) Bucket],"JUNE 26 PLANNED") -> 0 | BZ7: =BW7 -> 1 | CB7: =COUNTIFS(MASTER[ZH],$D7,MASTER[Planned (Month) Bucket],"JULY 26 PLANNED") -> 3 | CC7: =COUNTIFS(MASTER[ZH],$D7,MASTER[Planned (Month) Bucket],"JULY 26 PLANNED",MASTER[Actual (Month) Bucket],"JULY 26") -> 0 | CD7: =COUNTIFS(MASTER[EPC Status (Current Week)],CD$4,MASTER[ZH],$D7,MASTER[Planned (Month) Bucket],"JULY 26 PLANNED") -> 3 | CE7: =COUNTIFS(MASTER[EPC Status (Current Week)],CE$4,MASTER[ZH],$D7,MASTER[Planned (Month) Bucket],"JULY 26 PLANNED") -> 0 | CF7: =CC7 -> 0 | CH7: =COUNTIFS(MASTER[ZH],$D7,MASTER[Planned (Month) Bucket],"AUGUST 26 PLANNED") -> 0 | CI7: =COUNTIFS(MASTER[ZH],$D7,MASTER[Planned (Month) Bucket],"AUGUST 26 PLANNED",MASTER[Actual (Month) Bucket],"AUG 26") -> 0 | CJ7: =COUNTIFS(MASTER[EPC Status (Current Week)],CJ$4,MASTER[ZH],$D7,MASTER[Planned (Month) Bucket],"AUGUST 26 PLANNED") -> 0 | CK7: =COUNTIFS(MASTER[EPC Status (Current Week)],CK$4,MASTER[ZH],$D7,MASTER[Planned (Month) Bucket],"AUGUST 26 PLANNED") -> 0 | CL7: =CI7 -> 0
D8: KC | F8: =SUM(L8,Q8,Y8,AH8,AP8,AX8,BD8,BJ8,BP8) -> 54 | G8: =SUM(S8,AA8,AJ8,AR8,AZ8,BH8,BN8,BT8,BZ8) -> 39 | H8: =SUM(T8,AB8,AK8,AS8,BA8,BF8,BL8,BR8,BX8,CD8,CJ8) -> 21 | I8: =SUM(BG8,BM8,BS8,BY8,CE8,CK8) -> 0 | K8: =COUNTIFS(MASTER[ZH],$D8,MASTER[Planned (Month) Bucket],"March 25 PLANNED",MASTER[Actual (Month) Bucket],"April 25") -> 0 | L8: =COUNTIFS(MASTER[ZH],$D8,MASTER[Planned (Month) Bucket],"April 25 PLANNED") -> 0 | M8: =COUNTIFS(MASTER[ZH],$D8,MASTER[Planned (Month) Bucket],"April 25 PLANNED",MASTER[Actual (Month) Bucket],"April 25") -> 0 | O8: =COUNTIFS(MASTER[ZH],$D8,MASTER[Planned (Month) Bucket],"AUGUST 25 PLANNED",MASTER[Actual (Month) Bucket],"OCTOBER 25") -> 0 | P8: =COUNTIFS(MASTER[ZH],$D8,MASTER[Planned (Month) Bucket],"SEPTEMBER 25 PLANNED",MASTER[Actual (Month) Bucket],"OCTOBER 25") -> 0 | Q8: =COUNTIFS(MASTER[ZH],$D8,MASTER[Planned (Month) Bucket],"OCTOBER 25 PLANNED") -> 0 | R8: =COUNTIFS(MASTER[ZH],$D8,MASTER[Planned (Month) Bucket],"OCTOBER 25 PLANNED",MASTER[Actual (Month) Bucket],"OCTOBER 25") -> 0 | S8: =O8+P8+R8 -> 0 | T8: =COUNTIFS(MASTER[EPC Status (Current Week)],T$4,MASTER[ZH],$D8,MASTER[Planned (Month) Bucket],"OCTOBER 25 PLANNED") -> 0 | V8: =COUNTIFS(MASTER[ZH],$D8,MASTER[Planned (Month) Bucket],"AUGUST 25 PLANNED",MASTER[Actual (Month) Bucket],"NOVEMBER 25") -> 0 | W8: =COUNTIFS(MASTER[ZH],$D8,MASTER[Planned (Month) Bucket],"SEPTEMBER 25 PLANNED",MASTER[Actual (Month) Bucket],"NOVEMBER 25") -> 0 | X8: =COUNTIFS(MASTER[ZH],$D8,MASTER[Planned (Month) Bucket],"OCTOBER 25 PLANNED",MASTER[Actual (Month) Bucket],"NOVEMBER 25") -> 0 | Y8: =COUNTIFS(MASTER[ZH],$D8,MASTER[Planned (Month) Bucket],"NOVEMBER 25 PLANNED") -> 0 | Z8: =COUNTIFS(MASTER[ZH],$D8,MASTER[Planned (Month) Bucket],"NOVEMBER 25 PLANNED",MASTER[Actual (Month) Bucket],"NOVEMBER 25") -> 0 | AA8: =V8+W8+X8+Z8 -> 0 | AB8: =COUNTIFS(MASTER[EPC Status (Current Week)],AB$4,MASTER[ZH],$D8,MASTER[Planned (Month) Bucket],"NOVEMBER 25 PLANNED") -> 0 | AD8: =COUNTIFS(MASTER[ZH],$D8,MASTER[Planned (Month) Bucket],"AUGUST 25 PLANNED",MASTER[Actual (Month) Bucket],"DECEMBER 25") -> 0 | AE8: =COUNTIFS(MASTER[ZH],$D8,MASTER[Planned (Month) Bucket],"SEPTEMBER 25 PLANNED",MASTER[Actual (Month) Bucket],"DECEMBER 25") -> 0 | AF8: =COUNTIFS(MASTER[ZH],$D8,MASTER[Planned (Month) Bucket],"OCTOBER 25 PLANNED",MASTER[Actual (Month) Bucket],"DECEMBER 25") -> 0 | AG8: =COUNTIFS(MASTER[ZH],$D8,MASTER[Planned (Month) Bucket],"NOVEMBER 25 PLANNED",MASTER[Actual (Month) Bucket],"DECEMBER 25") -> 0 | AH8: =COUNTIFS(MASTER[ZH],$D8,MASTER[Planned (Month) Bucket],"DECEMBER 25 PLANNED") -> 0 | AI8: =COUNTIFS(MASTER[ZH],$D8,MASTER[Planned (Month) Bucket],"DECEMBER 25 PLANNED",MASTER[Actual (Month) Bucket],"DECEMBER 25") -> 0 | AJ8: =SUM(AD8,AE8,AF8,AG8,AI8) -> 0 | AK8: =COUNTIFS(MASTER[EPC Status (Current Week)],AK$4,MASTER[ZH],$D8,MASTER[Planned (Month) Bucket],"DECEMBER 25 PLANNED") -> 0 | AM8: =COUNTIFS(MASTER[ZH],$D8,MASTER[Planned (Month) Bucket],"OCTOBER 25 PLANNED",MASTER[Actual (Month) Bucket],"JANUARY 26") -> 0 | AN8: =COUNTIFS(MASTER[ZH],$D8,MASTER[Planned (Month) Bucket],"NOVEMBER 25 PLANNED",MASTER[Actual (Month) Bucket],"JANUARY 26") -> 0 | AO8: =COUNTIFS(MASTER[ZH],$D8,MASTER[Planned (Month) Bucket],"DECEMBER 25 PLANNED",MASTER[Actual (Month) Bucket],"JANUARY 26") -> 0 | AP8: =COUNTIFS(MASTER[ZH],$D8,MASTER[Planned (Month) Bucket],"JANUARY 26 PLANNED") -> 1 | AQ8: =COUNTIFS(MASTER[ZH],$D8,MASTER[Planned (Month) Bucket],"JANUARY 26 PLANNED",MASTER[Actual (Month) Bucket],"JANUARY 26") -> 0 | AR8: =SUM(AM8,AN8,AO8,AQ8) -> 0 | AS8: =COUNTIFS(MASTER[EPC Status (Current Week)],AS$4,MASTER[ZH],$D8,MASTER[Planned (Month) Bucket],"JANUARY 26 PLANNED") -> 1 | AU8: =COUNTIFS(MASTER[ZH],$D8,MASTER[Planned (Month) Bucket],"NOVEMBER 25 PLANNED",MASTER[Actual (Month) Bucket],"FEBRUARY 26") -> 0 | AV8: =COUNTIFS(MASTER[ZH],$D8,MASTER[Planned (Month) Bucket],"DECEMBER 25 PLANNED",MASTER[Actual (Month) Bucket],"FEBRUARY 26") -> 0 | AW8: =COUNTIFS(MASTER[ZH],$D8,MASTER[Planned (Month) Bucket],"JANUARY 26 PLANNED",MASTER[Actual (Month) Bucket],"FEBRUARY 26") -> 0 | AX8: =COUNTIFS(MASTER[ZH],$D8,MASTER[Planned (Month) Bucket],"FEBRUARY 26 PLANNED") -> 2 | AY8: =COUNTIFS(MASTER[ZH],$D8,MASTER[Planned (Month) Bucket],"FEBRUARY 26 PLANNED",MASTER[Actual (Month) Bucket],"FEBRUARY 26") -> 0 | AZ8: =SUM(AU8,AV8,AW8,AY8) -> 0 | BA8: =COUNTIFS(MASTER[EPC Status (Current Week)],BA$4,MASTER[ZH],$D8,MASTER[Planned (Month) Bucket],"FEBRUARY 26 PLANNED") -> 1 | BD8: =COUNTIFS(MASTER[ZH],$D8,MASTER[Planned (Month) Bucket],"MARCH 26 PLANNED") -> 15 | BE8: =COUNTIFS(MASTER[ZH],$D8,MASTER[Planned (Month) Bucket],"MARCH 26 PLANNED",MASTER[Actual (Month) Bucket],"MARCH 26")+COUNTIFS(MASTER[ZH],$D8,MASTER[Planned (Month) Bucket],"FEBRUARY 26 PLANNED",MASTER[Actual (Month) Bucket],"MARCH 26")+COUNTIFS(MASTER[ZH],$D8,MASTER[Planned (Month) Bucket],"JANUARY 26 PLANNED",MASTER[Actual (Month) Bucket],"MARCH 26")+COUNTIFS(MASTER[ZH],$D8,MASTER[Planned (Month) Bucket],"NOVEMBER 25 PLANNED",MASTER[Actual (Month) Bucket],"MARCH 26") -> 0 | BF8: =COUNTIFS(MASTER[EPC Status (Current Week)],BF$4,MASTER[ZH],$D8,MASTER[Planned (Month) Bucket],"MARCH 26 PLANNED") -> 0 | BG8: =COUNTIFS(MASTER[EPC Status (Current Week)],BG$4,MASTER[ZH],$D8,MASTER[Planned (Month) Bucket],"MARCH 26 PLANNED") -> 0 | BH8: =BE8 -> 0 | BJ8: =COUNTIFS(MASTER[ZH],$D8,MASTER[Planned (Month) Bucket],"APRIL 26 PLANNED") -> 13 | BK8: =COUNTIFS(MASTER[ZH],$D8,MASTER[Planned (Month) Bucket],"APRIL 26 PLANNED",MASTER[Actual (Month) Bucket],"APRIL 26")+COUNTIFS(MASTER[ZH],$D8,MASTER[Planned (Month) Bucket],"MARCH 26 PLANNED",MASTER[Actual (Month) Bucket],"APRIL 26")+COUNTIFS(MASTER[ZH],$D8,MASTER[Planned (Month) Bucket],"FEBRUARY 26 PLANNED",MASTER[Actual (Month) Bucket],"APRIL 26")+COUNTIFS(MASTER[ZH],$D8,MASTER[Planned (Month) Bucket],"JANUARY 26 PLANNED",MASTER[Actual (Month) Bucket],"APRIL 26")+COUNTIFS(MASTER[ZH],$D8,MASTER[Planned (Month) Bucket],"MAY 26 PLANNED",MASTER[Actual (Month) Bucket],"APRIL 26") -> 17 | BL8: =COUNTIFS(MASTER[EPC Status (Current Week)],BL$4,MASTER[ZH],$D8,MASTER[Planned (Month) Bucket],"APRIL 26 PLANNED") -> 6 | BM8: =COUNTIFS(MASTER[EPC Status (Current Week)],BM$4,MASTER[ZH],$D8,MASTER[Planned (Month) Bucket],"APRIL 26 PLANNED") -> 0 | BN8: =BK8 -> 17 | BP8: =COUNTIFS(MASTER[ZH],$D8,MASTER[Planned (Month) Bucket],"MAY 26 PLANNED") -> 23 | BQ8: =COUNTIFS(MASTER[ZH],$D8,MASTER[Planned (Month) Bucket],"NOVEMBER 25 PLANNED",MASTER[Actual (Month) Bucket],"MAY 26")+COUNTIFS(MASTER[ZH],$D8,MASTER[Planned (Month) Bucket],"DECEMBER 25 PLANNED",MASTER[Actual (Month) Bucket],"MAY 26")+COUNTIFS(MASTER[ZH],$D8,MASTER[Planned (Month) Bucket],"FEBRUARY 26 PLANNED",MASTER[Actual (Month) Bucket],"MAY 26")+COUNTIFS(MASTER[ZH],$D8,MASTER[Planned (Month) Bucket],"MARCH 26 PLANNED",MASTER[Actual (Month) Bucket],"MAY 26")+COUNTIFS(MASTER[ZH],$D8,MASTER[Planned (Month) Bucket],"APRIL 26 PLANNED",MASTER[Actual (Month) Bucket],"MAY 26")+COUNTIFS(MASTER[ZH],$D8,MASTER[Planned (Month) Bucket],"MAY 26 PLANNED",MASTER[Actual (Month) Bucket],"MAY 26") -> 19 | BR8: =COUNTIFS(MASTER[EPC Status (Current Week)],BR$4,MASTER[ZH],$D8,MASTER[Planned (Month) Bucket],"MAY 26 PLANNED") -> 7 | BS8: =COUNTIFS(MASTER[EPC Status (Current Week)],BS$4,MASTER[ZH],$D8,MASTER[Planned (Month) Bucket],"MAY 26 PLANNED") -> 0 | BT8: =BQ8 -> 19 | BV8: =COUNTIFS(MASTER[ZH],$D8,MASTER[Planned (Month) Bucket],"JUNE 26 PLANNED") -> 6 | BW8: =COUNTIFS(MASTER[ZH],$D8,MASTER[Planned (Month) Bucket],"JUNE 26 PLANNED",MASTER[Actual (Month) Bucket],"JUNE 26")+COUNTIFS(MASTER[ZH],$D8,MASTER[Planned (Month) Bucket],"MAY 26 PLANNED",MASTER[Actual (Month) Bucket],"JUNE 26")+COUNTIFS(MASTER[ZH],$D8,MASTER[Planned (Month) Bucket],"APRIL 26 PLANNED",MASTER[Actual (Month) Bucket],"JUNE 26")+COUNTIFS(MASTER[ZH],$D8,MASTER[Planned (Month) Bucket],"MARCH 26 PLANNED",MASTER[Actual (Month) Bucket],"JUNE 26")+COUNTIFS(MASTER[ZH],$D8,MASTER[Planned (Month) Bucket],"FEBRUARY 26 PLANNED",MASTER[Actual (Month) Bucket],"JUNE 26") -> 3 | BX8: =COUNTIFS(MASTER[EPC Status (Current Week)],BX$4,MASTER[ZH],$D8,MASTER[Planned (Month) Bucket],"JUNE 26 PLANNED") -> 6 | BY8: =COUNTIFS(MASTER[EPC Status (Current Week)],BY$4,MASTER[ZH],$D8,MASTER[Planned (Month) Bucket],"JUNE 26 PLANNED") -> 0 | BZ8: =BW8 -> 3 | CB8: =COUNTIFS(MASTER[ZH],$D8,MASTER[Planned (Month) Bucket],"JULY 26 PLANNED") -> 0 | CC8: =COUNTIFS(MASTER[ZH],$D8,MASTER[Planned (Month) Bucket],"JULY 26 PLANNED",MASTER[Actual (Month) Bucket],"JULY 26") -> 0 | CD8: =COUNTIFS(MASTER[EPC Status (Current Week)],CD$4,MASTER[ZH],$D8,MASTER[Planned (Month) Bucket],"JULY 26 PLANNED") -> 0 | CE8: =COUNTIFS(MASTER[EPC Status (Current Week)],CE$4,MASTER[ZH],$D8,MASTER[Planned (Month) Bucket],"JULY 26 PLANNED") -> 0 | CF8: =CC8 -> 0 | CH8: =COUNTIFS(MASTER[ZH],$D8,MASTER[Planned (Month) Bucket],"AUGUST 26 PLANNED") -> 0 | CI8: =COUNTIFS(MASTER[ZH],$D8,MASTER[Planned (Month) Bucket],"AUGUST 26 PLANNED",MASTER[Actual (Month) Bucket],"AUG 26") -> 0 | CJ8: =COUNTIFS(MASTER[EPC Status (Current Week)],CJ$4,MASTER[ZH],$D8,MASTER[Planned (Month) Bucket],"AUGUST 26 PLANNED") -> 0 | CK8: =COUNTIFS(MASTER[EPC Status (Current Week)],CK$4,MASTER[ZH],$D8,MASTER[Planned (Month) Bucket],"AUGUST 26 PLANNED") -> 0 | CL8: =CI8 -> 0
D9: TOTAL | F9: =SUM(F6:F8) -> 179 | G9: =SUM(G6:G8) -> 146 | H9: =SUM(H6:H8) -> 78 | I9: =SUM(I6:I8) -> 0 | K9: =SUM(K6:K8) -> 0 | L9: =SUM(L6:L8) -> 0 | M9: =SUM(M6:M8) -> 0 | O9: =SUM(O6:O8) -> 0 | P9: =SUM(P6:P8) -> 0 | Q9: =SUM(Q6:Q8) -> 0 | R9: =SUM(R6:R8) -> 0 | S9: =SUM(S6:S8) -> 0 | T9: =SUM(T6:T8) -> 0 | V9: =SUM(V6:V8) -> 0 | W9: =SUM(W6:W8) -> 0 | X9: =SUM(X6:X8) -> 0 | Y9: =SUM(Y6:Y8) -> 0 | Z9: =SUM(Z6:Z8) -> 0 | AA9: =SUM(AA6:AA8) -> 0 | AB9: =SUM(AB6:AB8) -> 0 | AD9: =SUM(AD6:AD8) -> 0 | AE9: =SUM(AE6:AE8) -> 0 | AF9: =SUM(AF6:AF8) -> 0 | AG9: =SUM(AG6:AG8) -> 0 | AH9: =SUM(AH6:AH8) -> 0 | AI9: =SUM(AI6:AI8) -> 0 | AJ9: =SUM(AJ6:AJ8) -> 0 | AK9: =SUM(AK6:AK8) -> 0 | AM9: =SUM(AM6:AM8) -> 0 | AN9: =SUM(AN6:AN8) -> 0 | AO9: =SUM(AO6:AO8) -> 0 | AP9: =SUM(AP6:AP8) -> 2 | AQ9: =SUM(AQ6:AQ8) -> 0 | AR9: =SUM(AR6:AR8) -> 0 | AS9: =SUM(AS6:AS8) -> 1 | AU9: =SUM(AU6:AU8) -> 0 | AV9: =SUM(AV6:AV8) -> 0 | AW9: =SUM(AW6:AW8) -> 0 | AX9: =SUM(AX6:AX8) -> 3 | AY9: =SUM(AY6:AY8) -> 0 | AZ9: =SUM(AZ6:AZ8) -> 0 | BA9: =SUM(BA6:BA8) -> 1 | BD9: =SUM(BD6:BD8) -> 60 | BE9: =SUM(BE6:BE8) -> 0 | BF9: =SUM(BF6:BF8) -> 1 | BG9: =SUM(BG6:BG8) -> 0 | BH9: =SUM(BH6:BH8) -> 0 | BJ9: =SUM(BJ6:BJ8) -> 33 | BK9: =SUM(BK6:BK8) -> 66 | BL9: =SUM(BL6:BL8) -> 9 | BM9: =SUM(BM6:BM8) -> 0 | BN9: =SUM(BN6:BN8) -> 66 | BP9: =SUM(BP6:BP8) -> 81 | BQ9: =SUM(BQ6:BQ8) -> 74 | BR9: =SUM(BR6:BR8) -> 21 | BS9: =SUM(BS6:BS8) -> 0 | BT9: =SUM(BT6:BT8) -> 74 | BV9: =SUM(BV6:BV8) -> 38 | BW9: =SUM(BW6:BW8) -> 6 | BX9: =SUM(BX6:BX8) -> 38 | BY9: =SUM(BY6:BY8) -> 0 | BZ9: =SUM(BZ6:BZ8) -> 6 | CB9: =SUM(CB6:CB8) -> 7 | CC9: =SUM(CC6:CC8) -> 0 | CD9: =SUM(CD6:CD8) -> 7 | CE9: =SUM(CE6:CE8) -> 0 | CF9: =SUM(CF6:CF8) -> 0 | CH9: =SUM(CH6:CH8) -> 0 | CI9: =SUM(CI6:CI8) -> 0 | CJ9: =SUM(CJ6:CJ8) -> 0 | CK9: =SUM(CK6:CK8) -> 0 | CL9: =SUM(CL6:CL8) -> 0
C10: SOUTH EAST | D10: SZ FO | F10: =SUM(L10,Q10,Y10,AH10,AP10,AX10,BD10,BJ10,BP10) -> 253 | G10: =SUM(S10,AA10,AJ10,AR10,AZ10,BH10,BN10,BT10,BZ10) -> 157 | H10: =SUM(T10,AB10,AK10,AS10,BA10,BF10,BL10,BR10,BX10,CD10,CJ10) -> 147 | I10: =SUM(BG10,BM10,BS10,BY10,CE10,CK10) -> 0 | K10: =COUNTIFS(MASTER[ZH],$D10,MASTER[Planned (Month) Bucket],"March 25 PLANNED",MASTER[Actual (Month) Bucket],"April 25") -> 0 | L10: =COUNTIFS(MASTER[ZH],$D10,MASTER[Planned (Month) Bucket],"April 25 PLANNED") -> 0 | M10: =COUNTIFS(MASTER[ZH],$D10,MASTER[Planned (Month) Bucket],"April 25 PLANNED",MASTER[Actual (Month) Bucket],"April 25") -> 0 | O10: =COUNTIFS(MASTER[ZH],$D10,MASTER[Planned (Month) Bucket],"AUGUST 25 PLANNED",MASTER[Actual (Month) Bucket],"OCTOBER 25") -> 0 | P10: =COUNTIFS(MASTER[ZH],$D10,MASTER[Planned (Month) Bucket],"SEPTEMBER 25 PLANNED",MASTER[Actual (Month) Bucket],"OCTOBER 25") -> 0 | Q10: =COUNTIFS(MASTER[ZH],$D10,MASTER[Planned (Month) Bucket],"OCTOBER 25 PLANNED") -> 0 | R10: =COUNTIFS(MASTER[ZH],$D10,MASTER[Planned (Month) Bucket],"OCTOBER 25 PLANNED",MASTER[Actual (Month) Bucket],"OCTOBER 25") -> 0 | S10: =O10+P10+R10 -> 0 | T10: =COUNTIFS(MASTER[EPC Status (Current Week)],T$4,MASTER[ZH],$D10,MASTER[Planned (Month) Bucket],"OCTOBER 25 PLANNED") -> 0 | V10: =COUNTIFS(MASTER[ZH],$D10,MASTER[Planned (Month) Bucket],"AUGUST 25 PLANNED",MASTER[Actual (Month) Bucket],"NOVEMBER 25") -> 0 | W10: =COUNTIFS(MASTER[ZH],$D10,MASTER[Planned (Month) Bucket],"SEPTEMBER 25 PLANNED",MASTER[Actual (Month) Bucket],"NOVEMBER 25") -> 0 | X10: =COUNTIFS(MASTER[ZH],$D10,MASTER[Planned (Month) Bucket],"OCTOBER 25 PLANNED",MASTER[Actual (Month) Bucket],"NOVEMBER 25") -> 0 | Y10: =COUNTIFS(MASTER[ZH],$D10,MASTER[Planned (Month) Bucket],"NOVEMBER 25 PLANNED") -> 0 | Z10: =COUNTIFS(MASTER[ZH],$D10,MASTER[Planned (Month) Bucket],"NOVEMBER 25 PLANNED",MASTER[Actual (Month) Bucket],"NOVEMBER 25") -> 0 | AA10: =V10+W10+X10+Z10 -> 0 | AB10: =COUNTIFS(MASTER[EPC Status (Current Week)],AB$4,MASTER[ZH],$D10,MASTER[Planned (Month) Bucket],"NOVEMBER 25 PLANNED") -> 0 | AD10: =COUNTIFS(MASTER[ZH],$D10,MASTER[Planned (Month) Bucket],"AUGUST 25 PLANNED",MASTER[Actual (Month) Bucket],"DECEMBER 25") -> 0 | AE10: =COUNTIFS(MASTER[ZH],$D10,MASTER[Planned (Month) Bucket],"SEPTEMBER 25 PLANNED",MASTER[Actual (Month) Bucket],"DECEMBER 25") -> 0 | AF10: =COUNTIFS(MASTER[ZH],$D10,MASTER[Planned (Month) Bucket],"OCTOBER 25 PLANNED",MASTER[Actual (Month) Bucket],"DECEMBER 25") -> 0 | AG10: =COUNTIFS(MASTER[ZH],$D10,MASTER[Planned (Month) Bucket],"NOVEMBER 25 PLANNED",MASTER[Actual (Month) Bucket],"DECEMBER 25") -> 0 | AH10: =COUNTIFS(MASTER[ZH],$D10,MASTER[Planned (Month) Bucket],"DECEMBER 25 PLANNED") -> 0 | AI10: =COUNTIFS(MASTER[ZH],$D10,MASTER[Planned (Month) Bucket],"DECEMBER 25 PLANNED",MASTER[Actual (Month) Bucket],"DECEMBER 25") -> 0 | AJ10: =SUM(AD10,AE10,AF10,AG10,AI10) -> 0 | AK10: =COUNTIFS(MASTER[EPC Status (Current Week)],AK$4,MASTER[ZH],$D10,MASTER[Planned (Month) Bucket],"DECEMBER 25 PLANNED") -> 0 | AM10: =COUNTIFS(MASTER[ZH],$D10,MASTER[Planned (Month) Bucket],"OCTOBER 25 PLANNED",MASTER[Actual (Month) Bucket],"JANUARY 26") -> 0 | AN10: =COUNTIFS(MASTER[ZH],$D10,MASTER[Planned (Month) Bucket],"NOVEMBER 25 PLANNED",MASTER[Actual (Month) Bucket],"JANUARY 26") -> 0 | AO10: =COUNTIFS(MASTER[ZH],$D10,MASTER[Planned (Month) Bucket],"DECEMBER 25 PLANNED",MASTER[Actual (Month) Bucket],"JANUARY 26") -> 0 | AP10: =COUNTIFS(MASTER[ZH],$D10,MASTER[Planned (Month) Bucket],"JANUARY 26 PLANNED") -> 0 | AQ10: =COUNTIFS(MASTER[ZH],$D10,MASTER[Planned (Month) Bucket],"JANUARY 26 PLANNED",MASTER[Actual (Month) Bucket],"JANUARY 26") -> 0 | AR10: =SUM(AM10,AN10,AO10,AQ10) -> 0 | AS10: =COUNTIFS(MASTER[EPC Status (Current Week)],AS$4,MASTER[ZH],$D10,MASTER[Planned (Month) Bucket],"JANUARY 26 PLANNED") -> 0 | AU10: =COUNTIFS(MASTER[ZH],$D10,MASTER[Planned (Month) Bucket],"NOVEMBER 25 PLANNED",MASTER[Actual (Month) Bucket],"FEBRUARY 26") -> 0 | AV10: =COUNTIFS(MASTER[ZH],$D10,MASTER[Planned (Month) Bucket],"DECEMBER 25 PLANNED",MASTER[Actual (Month) Bucket],"FEBRUARY 26") -> 0 | AW10: =COUNTIFS(MASTER[ZH],$D10,MASTER[Planned (Month) Bucket],"JANUARY 26 PLANNED",MASTER[Actual (Month) Bucket],"FEBRUARY 26") -> 0 | AX10: =COUNTIFS(MASTER[ZH],$D10,MASTER[Planned (Month) Bucket],"FEBRUARY 26 PLANNED") -> 13 | AY10: =COUNTIFS(MASTER[ZH],$D10,MASTER[Planned (Month) Bucket],"FEBRUARY 26 PLANNED",MASTER[Actual (Month) Bucket],"FEBRUARY 26") -> 0 | AZ10: =SUM(AU10,AV10,AW10,AY10) -> 0 | BA10: =COUNTIFS(MASTER[EPC Status (Current Week)],BA$4,MASTER[ZH],$D10,MASTER[Planned (Month) Bucket],"FEBRUARY 26 PLANNED") -> 5 | BD10: =COUNTIFS(MASTER[ZH],$D10,MASTER[Planned (Month) Bucket],"MARCH 26 PLANNED") -> 30 | BE10: =COUNTIFS(MASTER[ZH],$D10,MASTER[Planned (Month) Bucket],"MARCH 26 PLANNED",MASTER[Actual (Month) Bucket],"MARCH 26")+COUNTIFS(MASTER[ZH],$D10,MASTER[Planned (Month) Bucket],"FEBRUARY 26 PLANNED",MASTER[Actual (Month) Bucket],"MARCH 26")+COUNTIFS(MASTER[ZH],$D10,MASTER[Planned (Month) Bucket],"JANUARY 26 PLANNED",MASTER[Actual (Month) Bucket],"MARCH 26") -> 0 | BF10: =COUNTIFS(MASTER[EPC Status (Current Week)],BF$4,MASTER[ZH],$D10,MASTER[Planned (Month) Bucket],"MARCH 26 PLANNED") -> 6 | BG10: =COUNTIFS(MASTER[EPC Status (Current Week)],BG$4,MASTER[ZH],$D10,MASTER[Planned (Month) Bucket],"MARCH 26 PLANNED") -> 0 | BH10: =BE10 -> 0 | BJ10: =COUNTIFS(MASTER[ZH],$D10,MASTER[Planned (Month) Bucket],"APRIL 26 PLANNED") -> 154 | BK10: =COUNTIFS(MASTER[ZH],$D10,MASTER[Planned (Month) Bucket],"APRIL 26 PLANNED",MASTER[Actual (Month) Bucket],"APRIL 26")+COUNTIFS(MASTER[ZH],$D10,MASTER[Planned (Month) Bucket],"MARCH 26 PLANNED",MASTER[Actual (Month) Bucket],"APRIL 26")+COUNTIFS(MASTER[ZH],$D10,MASTER[Planned (Month) Bucket],"FEBRUARY 26 PLANNED",MASTER[Actual (Month) Bucket],"APRIL 26")+COUNTIFS(MASTER[ZH],$D10,MASTER[Planned (Month) Bucket],"JANUARY 26 PLANNED",MASTER[Actual (Month) Bucket],"APRIL 26")+COUNTIFS(MASTER[ZH],$D10,MASTER[Planned (Month) Bucket],"MAY 26 PLANNED",MASTER[Actual (Month) Bucket],"APRIL 26") -> 41 | BL10: =COUNTIFS(MASTER[EPC Status (Current Week)],BL$4,MASTER[ZH],$D10,MASTER[Planned (Month) Bucket],"APRIL 26 PLANNED") -> 66 | BM10: =COUNTIFS(MASTER[EPC Status (Current Week)],BM$4,MASTER[ZH],$D10,MASTER[Planned (Month) Bucket],"APRIL 26 PLANNED") -> 0 | BN10: =BK10 -> 41 | BP10: =COUNTIFS(MASTER[ZH],$D10,MASTER[Planned (Month) Bucket],"MAY 26 PLANNED") -> 56 | BQ10: =COUNTIFS(MASTER[ZH],$D10,MASTER[Planned (Month) Bucket],"NOVEMBER 25 PLANNED",MASTER[Actual (Month) Bucket],"MAY 26")+COUNTIFS(MASTER[ZH],$D10,MASTER[Planned (Month) Bucket],"DECEMBER 25 PLANNED",MASTER[Actual (Month) Bucket],"MAY 26")+COUNTIFS(MASTER[ZH],$D10,MASTER[Planned (Month) Bucket],"FEBRUARY 26 PLANNED",MASTER[Actual (Month) Bucket],"MAY 26")+COUNTIFS(MASTER[ZH],$D10,MASTER[Planned (Month) Bucket],"MARCH 26 PLANNED",MASTER[Actual (Month) Bucket],"MAY 26")+COUNTIFS(MASTER[ZH],$D10,MASTER[Planned (Month) Bucket],"APRIL 26 PLANNED",MASTER[Actual (Month) Bucket],"MAY 26")+COUNTIFS(MASTER[ZH],$D10,MASTER[Planned (Month) Bucket],"MAY 26 PLANNED",MASTER[Actual (Month) Bucket],"MAY 26") -> 102 | BR10: =COUNTIFS(MASTER[EPC Status (Current Week)],BR$4,MASTER[ZH],$D10,MASTER[Planned (Month) Bucket],"MAY 26 PLANNED") -> 26 | BS10: =COUNTIFS(MASTER[EPC Status (Current Week)],BS$4,MASTER[ZH],$D10,MASTER[Planned (Month) Bucket],"MAY 26 PLANNED") -> 0 | BT10: =BQ10 -> 102 | BV10: =COUNTIFS(MASTER[ZH],$D10,MASTER[Planned (Month) Bucket],"JUNE 26 PLANNED") -> 49 | BW10: =COUNTIFS(MASTER[ZH],$D10,MASTER[Planned (Month) Bucket],"JUNE 26 PLANNED",MASTER[Actual (Month) Bucket],"JUNE 26")+COUNTIFS(MASTER[ZH],$D10,MASTER[Planned (Month) Bucket],"MAY 26 PLANNED",MASTER[Actual (Month) Bucket],"JUNE 26")+COUNTIFS(MASTER[ZH],$D10,MASTER[Planned (Month) Bucket],"APRIL 26 PLANNED",MASTER[Actual (Month) Bucket],"JUNE 26")+COUNTIFS(MASTER[ZH],$D10,MASTER[Planned (Month) Bucket],"MARCH 26 PLANNED",MASTER[Actual (Month) Bucket],"JUNE 26")+COUNTIFS(MASTER[ZH],$D10,MASTER[Planned (Month) Bucket],"FEBRUARY 26 PLANNED",MASTER[Actual (Month) Bucket],"JUNE 26") -> 14 | BX10: =COUNTIFS(MASTER[EPC Status (Current Week)],BX$4,MASTER[ZH],$D10,MASTER[Planned (Month) Bucket],"JUNE 26 PLANNED") -> 42 | BY10: =COUNTIFS(MASTER[EPC Status (Current Week)],BY$4,MASTER[ZH],$D10,MASTER[Planned (Month) Bucket],"JUNE 26 PLANNED") -> 0 | BZ10: =BW10 -> 14 | CB10: =COUNTIFS(MASTER[ZH],$D10,MASTER[Planned (Month) Bucket],"JULY 26 PLANNED") -> 2 | CC10: =COUNTIFS(MASTER[ZH],$D10,MASTER[Planned (Month) Bucket],"JULY 26 PLANNED",MASTER[Actual (Month) Bucket],"JULY 26") -> 0 | CD10: =COUNTIFS(MASTER[EPC Status (Current Week)],CD$4,MASTER[ZH],$D10,MASTER[Planned (Month) Bucket],"JULY 26 PLANNED") -> 2 | CE10: =COUNTIFS(MASTER[EPC Status (Current Week)],CE$4,MASTER[ZH],$D10,MASTER[Planned (Month) Bucket],"JULY 26 PLANNED") -> 0 | CF10: =CC10 -> 0 | CH10: =COUNTIFS(MASTER[ZH],$D10,MASTER[Planned (Month) Bucket],"AUGUST 26 PLANNED") -> 0 | CI10: =COUNTIFS(MASTER[ZH],$D10,MASTER[Planned (Month) Bucket],"AUGUST 26 PLANNED",MASTER[Actual (Month) Bucket],"AUG 26") -> 0 | CJ10: =COUNTIFS(MASTER[EPC Status (Current Week)],CJ$4,MASTER[ZH],$D10,MASTER[Planned (Month) Bucket],"AUGUST 26 PLANNED") -> 0 | CK10: =COUNTIFS(MASTER[EPC Status (Current Week)],CK$4,MASTER[ZH],$D10,MASTER[Planned (Month) Bucket],"AUGUST 26 PLANNED") -> 0 | CL10: =CI10 -> 0
D11: SD | F11: =SUM(L11,Q11,Y11,AH11,AP11,AX11,BD11,BJ11,BP11) -> 391 | G11: =SUM(S11,AA11,AJ11,AR11,AZ11,BH11,BN11,BT11,BZ11) -> 352 | H11: =SUM(T11,AB11,AK11,AS11,BA11,BF11,BL11,BR11,BX11,CD11,CJ11) -> 105 | I11: =SUM(BG11,BM11,BS11,BY11,CE11,CK11) -> 0 | K11: =COUNTIFS(MASTER[ZH],$D11,MASTER[Planned (Month) Bucket],"March 25 PLANNED",MASTER[Actual (Month) Bucket],"April 25") -> 0 | L11: =COUNTIFS(MASTER[ZH],$D11,MASTER[Planned (Month) Bucket],"April 25 PLANNED") -> 0 | M11: =COUNTIFS(MASTER[ZH],$D11,MASTER[Planned (Month) Bucket],"April 25 PLANNED",MASTER[Actual (Month) Bucket],"April 25") -> 0 | O11: =COUNTIFS(MASTER[ZH],$D11,MASTER[Planned (Month) Bucket],"AUGUST 25 PLANNED",MASTER[Actual (Month) Bucket],"OCTOBER 25") -> 0 | P11: =COUNTIFS(MASTER[ZH],$D11,MASTER[Planned (Month) Bucket],"SEPTEMBER 25 PLANNED",MASTER[Actual (Month) Bucket],"OCTOBER 25") -> 0 | Q11: =COUNTIFS(MASTER[ZH],$D11,MASTER[Planned (Month) Bucket],"OCTOBER 25 PLANNED") -> 0 | R11: =COUNTIFS(MASTER[ZH],$D11,MASTER[Planned (Month) Bucket],"OCTOBER 25 PLANNED",MASTER[Actual (Month) Bucket],"OCTOBER 25") -> 0 | S11: =O11+P11+R11 -> 0 | T11: =COUNTIFS(MASTER[EPC Status (Current Week)],T$4,MASTER[ZH],$D11,MASTER[Planned (Month) Bucket],"OCTOBER 25 PLANNED") -> 0 | V11: =COUNTIFS(MASTER[ZH],$D11,MASTER[Planned (Month) Bucket],"AUGUST 25 PLANNED",MASTER[Actual (Month) Bucket],"NOVEMBER 25") -> 0 | W11: =COUNTIFS(MASTER[ZH],$D11,MASTER[Planned (Month) Bucket],"SEPTEMBER 25 PLANNED",MASTER[Actual (Month) Bucket],"NOVEMBER 25") -> 0 | X11: =COUNTIFS(MASTER[ZH],$D11,MASTER[Planned (Month) Bucket],"OCTOBER 25 PLANNED",MASTER[Actual (Month) Bucket],"NOVEMBER 25") -> 0 | Y11: =COUNTIFS(MASTER[ZH],$D11,MASTER[Planned (Month) Bucket],"NOVEMBER 25 PLANNED") -> 0 | Z11: =COUNTIFS(MASTER[ZH],$D11,MASTER[Planned (Month) Bucket],"NOVEMBER 25 PLANNED",MASTER[Actual (Month) Bucket],"NOVEMBER 25") -> 0 | AA11: =V11+W11+X11+Z11 -> 0 | AB11: =COUNTIFS(MASTER[EPC Status (Current Week)],AB$4,MASTER[ZH],$D11,MASTER[Planned (Month) Bucket],"NOVEMBER 25 PLANNED") -> 0 | AD11: =COUNTIFS(MASTER[ZH],$D11,MASTER[Planned (Month) Bucket],"AUGUST 25 PLANNED",MASTER[Actual (Month) Bucket],"DECEMBER 25") -> 0 | AE11: =COUNTIFS(MASTER[ZH],$D11,MASTER[Planned (Month) Bucket],"SEPTEMBER 25 PLANNED",MASTER[Actual (Month) Bucket],"DECEMBER 25") -> 0 | AF11: =COUNTIFS(MASTER[ZH],$D11,MASTER[Planned (Month) Bucket],"OCTOBER 25 PLANNED",MASTER[Actual (Month) Bucket],"DECEMBER 25") -> 0 | AG11: =COUNTIFS(MASTER[ZH],$D11,MASTER[Planned (Month) Bucket],"NOVEMBER 25 PLANNED",MASTER[Actual (Month) Bucket],"DECEMBER 25") -> 0 | AH11: =COUNTIFS(MASTER[ZH],$D11,MASTER[Planned (Month) Bucket],"DECEMBER 25 PLANNED") -> 0 | AI11: =COUNTIFS(MASTER[ZH],$D11,MASTER[Planned (Month) Bucket],"DECEMBER 25 PLANNED",MASTER[Actual (Month) Bucket],"DECEMBER 25") -> 0 | AJ11: =SUM(AD11,AE11,AF11,AG11,AI11) -> 0 | AK11: =COUNTIFS(MASTER[EPC Status (Current Week)],AK$4,MASTER[ZH],$D11,MASTER[Planned (Month) Bucket],"DECEMBER 25 PLANNED") -> 0 | AM11: =COUNTIFS(MASTER[ZH],$D11,MASTER[Planned (Month) Bucket],"OCTOBER 25 PLANNED",MASTER[Actual (Month) Bucket],"JANUARY 26") -> 0 | AN11: =COUNTIFS(MASTER[ZH],$D11,MASTER[Planned (Month) Bucket],"NOVEMBER 25 PLANNED",MASTER[Actual (Month) Bucket],"JANUARY 26") -> 0 | AO11: =COUNTIFS(MASTER[ZH],$D11,MASTER[Planned (Month) Bucket],"DECEMBER 25 PLANNED",MASTER[Actual (Month) Bucket],"JANUARY 26") -> 0 | AP11: =COUNTIFS(MASTER[ZH],$D11,MASTER[Planned (Month) Bucket],"JANUARY 26 PLANNED") -> 0 | AQ11: =COUNTIFS(MASTER[ZH],$D11,MASTER[Planned (Month) Bucket],"JANUARY 26 PLANNED",MASTER[Actual (Month) Bucket],"JANUARY 26") -> 0 | AR11: =SUM(AM11,AN11,AO11,AQ11) -> 0 | AS11: =COUNTIFS(MASTER[EPC Status (Current Week)],AS$4,MASTER[ZH],$D11,MASTER[Planned (Month) Bucket],"JANUARY 26 PLANNED") -> 0 | AU11: =COUNTIFS(MASTER[ZH],$D11,MASTER[Planned (Month) Bucket],"NOVEMBER 25 PLANNED",MASTER[Actual (Month) Bucket],"FEBRUARY 26") -> 0 | AV11: =COUNTIFS(MASTER[ZH],$D11,MASTER[Planned (Month) Bucket],"DECEMBER 25 PLANNED",MASTER[Actual (Month) Bucket],"FEBRUARY 26") -> 0 | AW11: =COUNTIFS(MASTER[ZH],$D11,MASTER[Planned (Month) Bucket],"JANUARY 26 PLANNED",MASTER[Actual (Month) Bucket],"FEBRUARY 26") -> 0 | AX11: =COUNTIFS(MASTER[ZH],$D11,MASTER[Planned (Month) Bucket],"FEBRUARY 26 PLANNED") -> 13 | AY11: =COUNTIFS(MASTER[ZH],$D11,MASTER[Planned (Month) Bucket],"FEBRUARY 26 PLANNED",MASTER[Actual (Month) Bucket],"FEBRUARY 26") -> 0 | AZ11: =SUM(AU11,AV11,AW11,AY11) -> 0 | BA11: =COUNTIFS(MASTER[EPC Status (Current Week)],BA$4,MASTER[ZH],$D11,MASTER[Planned (Month) Bucket],"FEBRUARY 26 PLANNED") -> 0 | BD11: =COUNTIFS(MASTER[ZH],$D11,MASTER[Planned (Month) Bucket],"MARCH 26 PLANNED") -> 137 | BE11: =COUNTIFS(MASTER[ZH],$D11,MASTER[Planned (Month) Bucket],"MARCH 26 PLANNED",MASTER[Actual (Month) Bucket],"MARCH 26")+COUNTIFS(MASTER[ZH],$D11,MASTER[Planned (Month) Bucket],"FEBRUARY 26 PLANNED",MASTER[Actual (Month) Bucket],"MARCH 26")+COUNTIFS(MASTER[ZH],$D11,MASTER[Planned (Month) Bucket],"JANUARY 26 PLANNED",MASTER[Actual (Month) Bucket],"MARCH 26") -> 0 | BF11: =COUNTIFS(MASTER[EPC Status (Current Week)],BF$4,MASTER[ZH],$D11,MASTER[Planned (Month) Bucket],"MARCH 26 PLANNED") -> 7 | BG11: =COUNTIFS(MASTER[EPC Status (Current Week)],BG$4,MASTER[ZH],$D11,MASTER[Planned (Month) Bucket],"MARCH 26 PLANNED") -> 0 | BH11: =BE11 -> 0 | BJ11: =COUNTIFS(MASTER[ZH],$D11,MASTER[Planned (Month) Bucket],"APRIL 26 PLANNED") -> 103 | BK11: =COUNTIFS(MASTER[ZH],$D11,MASTER[Planned (Month) Bucket],"APRIL 26 PLANNED",MASTER[Actual (Month) Bucket],"APRIL 26")+COUNTIFS(MASTER[ZH],$D11,MASTER[Planned (Month) Bucket],"MARCH 26 PLANNED",MASTER[Actual (Month) Bucket],"APRIL 26")+COUNTIFS(MASTER[ZH],$D11,MASTER[Planned (Month) Bucket],"FEBRUARY 26 PLANNED",MASTER[Actual (Month) Bucket],"APRIL 26")+COUNTIFS(MASTER[ZH],$D11,MASTER[Planned (Month) Bucket],"JANUARY 26 PLANNED",MASTER[Actual (Month) Bucket],"APRIL 26")+COUNTIFS(MASTER[ZH],$D11,MASTER[Planned (Month) Bucket],"MAY 26 PLANNED",MASTER[Actual (Month) Bucket],"APRIL 26") -> 157 | BL11: =COUNTIFS(MASTER[EPC Status (Current Week)],BL$4,MASTER[ZH],$D11,MASTER[Planned (Month) Bucket],"APRIL 26 PLANNED") -> 10 | BM11: =COUNTIFS(MASTER[EPC Status (Current Week)],BM$4,MASTER[ZH],$D11,MASTER[Planned (Month) Bucket],"APRIL 26 PLANNED") -> 0 | BN11: =BK11 -> 157 | BP11: =COUNTIFS(MASTER[ZH],$D11,MASTER[Planned (Month) Bucket],"MAY 26 PLANNED") -> 138 | BQ11: =COUNTIFS(MASTER[ZH],$D11,MASTER[Planned (Month) Bucket],"NOVEMBER 25 PLANNED",MASTER[Actual (Month) Bucket],"MAY 26")+COUNTIFS(MASTER[ZH],$D11,MASTER[Planned (Month) Bucket],"DECEMBER 25 PLANNED",MASTER[Actual (Month) Bucket],"MAY 26")+COUNTIFS(MASTER[ZH],$D11,MASTER[Planned (Month) Bucket],"FEBRUARY 26 PLANNED",MASTER[Actual (Month) Bucket],"MAY 26")+COUNTIFS(MASTER[ZH],$D11,MASTER[Planned (Month) Bucket],"MARCH 26 PLANNED",MASTER[Actual (Month) Bucket],"MAY 26")+COUNTIFS(MASTER[ZH],$D11,MASTER[Planned (Month) Bucket],"APRIL 26 PLANNED",MASTER[Actual (Month) Bucket],"MAY 26")+COUNTIFS(MASTER[ZH],$D11,MASTER[Planned (Month) Bucket],"MAY 26 PLANNED",MASTER[Actual (Month) Bucket],"MAY 26") -> 187 | BR11: =COUNTIFS(MASTER[EPC Status (Current Week)],BR$4,MASTER[ZH],$D11,MASTER[Planned (Month) Bucket],"MAY 26 PLANNED") -> 23 | BS11: =COUNTIFS(MASTER[EPC Status (Current Week)],BS$4,MASTER[ZH],$D11,MASTER[Planned (Month) Bucket],"MAY 26 PLANNED") -> 0 | BT11: =BQ11 -> 187 | BV11: =COUNTIFS(MASTER[ZH],$D11,MASTER[Planned (Month) Bucket],"JUNE 26 PLANNED") -> 61 | BW11: =COUNTIFS(MASTER[ZH],$D11,MASTER[Planned (Month) Bucket],"JUNE 26 PLANNED",MASTER[Actual (Month) Bucket],"JUNE 26")+COUNTIFS(MASTER[ZH],$D11,MASTER[Planned (Month) Bucket],"MAY 26 PLANNED",MASTER[Actual (Month) Bucket],"JUNE 26")+COUNTIFS(MASTER[ZH],$D11,MASTER[Planned (Month) Bucket],"APRIL 26 PLANNED",MASTER[Actual (Month) Bucket],"JUNE 26")+COUNTIFS(MASTER[ZH],$D11,MASTER[Planned (Month) Bucket],"MARCH 26 PLANNED",MASTER[Actual (Month) Bucket],"JUNE 26")+COUNTIFS(MASTER[ZH],$D11,MASTER[Planned (Month) Bucket],"FEBRUARY 26 PLANNED",MASTER[Actual (Month) Bucket],"JUNE 26") -> 8 | BX11: =COUNTIFS(MASTER[EPC Status (Current Week)],BX$4,MASTER[ZH],$D11,MASTER[Planned (Month) Bucket],"JUNE 26 PLANNED") -> 60 | BY11: =COUNTIFS(MASTER[EPC Status (Current Week)],BY$4,MASTER[ZH],$D11,MASTER[Planned (Month) Bucket],"JUNE 26 PLANNED") -> 0 | BZ11: =BW11 -> 8 | CB11: =COUNTIFS(MASTER[ZH],$D11,MASTER[Planned (Month) Bucket],"JULY 26 PLANNED") -> 5 | CC11: =COUNTIFS(MASTER[ZH],$D11,MASTER[Planned (Month) Bucket],"JULY 26 PLANNED",MASTER[Actual (Month) Bucket],"JULY 26") -> 0 | CD11: =COUNTIFS(MASTER[EPC Status (Current Week)],CD$4,MASTER[ZH],$D11,MASTER[Planned (Month) Bucket],"JULY 26 PLANNED") -> 5 | CE11: =COUNTIFS(MASTER[EPC Status (Current Week)],CE$4,MASTER[ZH],$D11,MASTER[Planned (Month) Bucket],"JULY 26 PLANNED") -> 0 | CF11: =CC11 -> 0 | CH11: =COUNTIFS(MASTER[ZH],$D11,MASTER[Planned (Month) Bucket],"AUGUST 26 PLANNED") -> 0 | CI11: =COUNTIFS(MASTER[ZH],$D11,MASTER[Planned (Month) Bucket],"AUGUST 26 PLANNED",MASTER[Actual (Month) Bucket],"AUG 26") -> 0 | CJ11: =COUNTIFS(MASTER[EPC Status (Current Week)],CJ$4,MASTER[ZH],$D11,MASTER[Planned (Month) Bucket],"AUGUST 26 PLANNED") -> 0 | CK11: =COUNTIFS(MASTER[EPC Status (Current Week)],CK$4,MASTER[ZH],$D11,MASTER[Planned (Month) Bucket],"AUGUST 26 PLANNED") -> 0 | CL11: =CI11 -> 0
D12: AK | F12: =SUM(L12,Q12,Y12,AH12,AP12,AX12,BD12,BJ12,BP12) -> 99 | G12: =SUM(S12,AA12,AJ12,AR12,AZ12,BH12,BN12,BT12,BZ12) -> 58 | H12: =SUM(T12,AB12,AK12,AS12,BA12,BF12,BL12,BR12,BX12,CD12,CJ12) -> 52 | I12: =SUM(BG12,BM12,BS12,BY12,CE12,CK12) -> 2 | K12: =COUNTIFS(MASTER[ZH],$D12,MASTER[Planned (Month) Bucket],"March 25 PLANNED",MASTER[Actual (Month) Bucket],"April 25") -> 0 | L12: =COUNTIFS(MASTER[ZH],$D12,MASTER[Planned (Month) Bucket],"April 25 PLANNED") -> 0 | M12: =COUNTIFS(MASTER[ZH],$D12,MASTER[Planned (Month) Bucket],"April 25 PLANNED",MASTER[Actual (Month) Bucket],"April 25") -> 0 | O12: =COUNTIFS(MASTER[ZH],$D12,MASTER[Planned (Month) Bucket],"AUGUST 25 PLANNED",MASTER[Actual (Month) Bucket],"OCTOBER 25") -> 0 | P12: =COUNTIFS(MASTER[ZH],$D12,MASTER[Planned (Month) Bucket],"SEPTEMBER 25 PLANNED",MASTER[Actual (Month) Bucket],"OCTOBER 25") -> 0 | Q12: =COUNTIFS(MASTER[ZH],$D12,MASTER[Planned (Month) Bucket],"OCTOBER 25 PLANNED") -> 0 | R12: =COUNTIFS(MASTER[ZH],$D12,MASTER[Planned (Month) Bucket],"OCTOBER 25 PLANNED",MASTER[Actual (Month) Bucket],"OCTOBER 25") -> 0 | S12: =O12+P12+R12 -> 0 | T12: =COUNTIFS(MASTER[EPC Status (Current Week)],T$4,MASTER[ZH],$D12,MASTER[Planned (Month) Bucket],"OCTOBER 25 PLANNED") -> 0 | V12: =COUNTIFS(MASTER[ZH],$D12,MASTER[Planned (Month) Bucket],"AUGUST 25 PLANNED",MASTER[Actual (Month) Bucket],"NOVEMBER 25") -> 0 | W12: =COUNTIFS(MASTER[ZH],$D12,MASTER[Planned (Month) Bucket],"SEPTEMBER 25 PLANNED",MASTER[Actual (Month) Bucket],"NOVEMBER 25") -> 0 | X12: =COUNTIFS(MASTER[ZH],$D12,MASTER[Planned (Month) Bucket],"OCTOBER 25 PLANNED",MASTER[Actual (Month) Bucket],"NOVEMBER 25") -> 0 | Y12: =COUNTIFS(MASTER[ZH],$D12,MASTER[Planned (Month) Bucket],"NOVEMBER 25 PLANNED") -> 1 | Z12: =COUNTIFS(MASTER[ZH],$D12,MASTER[Planned (Month) Bucket],"NOVEMBER 25 PLANNED",MASTER[Actual (Month) Bucket],"NOVEMBER 25") -> 0 | AA12: =V12+W12+X12+Z12 -> 0 | AB12: =COUNTIFS(MASTER[EPC Status (Current Week)],AB$4,MASTER[ZH],$D12,MASTER[Planned (Month) Bucket],"NOVEMBER 25 PLANNED") -> 0 | AD12: =COUNTIFS(MASTER[ZH],$D12,MASTER[Planned (Month) Bucket],"AUGUST 25 PLANNED",MASTER[Actual (Month) Bucket],"DECEMBER 25") -> 0 | AE12: =COUNTIFS(MASTER[ZH],$D12,MASTER[Planned (Month) Bucket],"SEPTEMBER 25 PLANNED",MASTER[Actual (Month) Bucket],"DECEMBER 25") -> 0 | AF12: =COUNTIFS(MASTER[ZH],$D12,MASTER[Planned (Month) Bucket],"OCTOBER 25 PLANNED",MASTER[Actual (Month) Bucket],"DECEMBER 25") -> 0 | AG12: =COUNTIFS(MASTER[ZH],$D12,MASTER[Planned (Month) Bucket],"NOVEMBER 25 PLANNED",MASTER[Actual (Month) Bucket],"DECEMBER 25") -> 0 | AH12: =COUNTIFS(MASTER[ZH],$D12,MASTER[Planned (Month) Bucket],"DECEMBER 25 PLANNED") -> 1 | AI12: =COUNTIFS(MASTER[ZH],$D12,MASTER[Planned (Month) Bucket],"DECEMBER 25 PLANNED",MASTER[Actual (Month) Bucket],"DECEMBER 25") -> 0 | AJ12: =SUM(AD12,AE12,AF12,AG12,AI12) -> 0 | AK12: =COUNTIFS(MASTER[EPC Status (Current Week)],AK$4,MASTER[ZH],$D12,MASTER[Planned (Month) Bucket],"DECEMBER 25 PLANNED") -> 0 | AM12: =COUNTIFS(MASTER[ZH],$D12,MASTER[Planned (Month) Bucket],"OCTOBER 25 PLANNED",MASTER[Actual (Month) Bucket],"JANUARY 26") -> 0 | AN12: =COUNTIFS(MASTER[ZH],$D12,MASTER[Planned (Month) Bucket],"NOVEMBER 25 PLANNED",MASTER[Actual (Month) Bucket],"JANUARY 26") -> 0 | AO12: =COUNTIFS(MASTER[ZH],$D12,MASTER[Planned (Month) Bucket],"DECEMBER 25 PLANNED",MASTER[Actual (Month) Bucket],"JANUARY 26") -> 0 | AP12: =COUNTIFS(MASTER[ZH],$D12,MASTER[Planned (Month) Bucket],"JANUARY 26 PLANNED") -> 2 | AQ12: =COUNTIFS(MASTER[ZH],$D12,MASTER[Planned (Month) Bucket],"JANUARY 26 PLANNED",MASTER[Actual (Month) Bucket],"JANUARY 26") -> 0 | AR12: =SUM(AM12,AN12,AO12,AQ12) -> 0 | AS12: =COUNTIFS(MASTER[EPC Status (Current Week)],AS$4,MASTER[ZH],$D12,MASTER[Planned (Month) Bucket],"JANUARY 26 PLANNED") -> 2 | AU12: =COUNTIFS(MASTER[ZH],$D12,MASTER[Planned (Month) Bucket],"NOVEMBER 25 PLANNED",MASTER[Actual (Month) Bucket],"FEBRUARY 26") -> 0 | AV12: =COUNTIFS(MASTER[ZH],$D12,MASTER[Planned (Month) Bucket],"DECEMBER 25 PLANNED",MASTER[Actual (Month) Bucket],"FEBRUARY 26") -> 0 | AW12: =COUNTIFS(MASTER[ZH],$D12,MASTER[Planned (Month) Bucket],"JANUARY 26 PLANNED",MASTER[Actual (Month) Bucket],"FEBRUARY 26") -> 0 | AX12: =COUNTIFS(MASTER[ZH],$D12,MASTER[Planned (Month) Bucket],"FEBRUARY 26 PLANNED") -> 6 | AY12: =COUNTIFS(MASTER[ZH],$D12,MASTER[Planned (Month) Bucket],"FEBRUARY 26 PLANNED",MASTER[Actual (Month) Bucket],"FEBRUARY 26") -> 0 | AZ12: =SUM(AU12,AV12,AW12,AY12) -> 0 | BA12: =COUNTIFS(MASTER[EPC Status (Current Week)],BA$4,MASTER[ZH],$D12,MASTER[Planned (Month) Bucket],"FEBRUARY 26 PLANNED") -> 1 | BD12: =COUNTIFS(MASTER[ZH],$D12,MASTER[Planned (Month) Bucket],"MARCH 26 PLANNED") -> 23 | BE12: =COUNTIFS(MASTER[ZH],$D12,MASTER[Planned (Month) Bucket],"MARCH 26 PLANNED",MASTER[Actual (Month) Bucket],"MARCH 26")+COUNTIFS(MASTER[ZH],$D12,MASTER[Planned (Month) Bucket],"FEBRUARY 26 PLANNED",MASTER[Actual (Month) Bucket],"MARCH 26")+COUNTIFS(MASTER[ZH],$D12,MASTER[Planned (Month) Bucket],"JANUARY 26 PLANNED",MASTER[Actual (Month) Bucket],"MARCH 26")++COUNTIFS(MASTER[ZH],$D12,MASTER[Planned (Month) Bucket],"NOVEMBER 25 PLANNED",MASTER[Actual (Month) Bucket],"MARCH 26") -> 0 | BF12: =COUNTIFS(MASTER[EPC Status (Current Week)],BF$4,MASTER[ZH],$D12,MASTER[Planned (Month) Bucket],"MARCH 26 PLANNED") -> 10 | BG12: =COUNTIFS(MASTER[EPC Status (Current Week)],BG$4,MASTER[ZH],$D12,MASTER[Planned (Month) Bucket],"MARCH 26 PLANNED") -> 0 | BH12: =BE12 -> 0 | BJ12: =COUNTIFS(MASTER[ZH],$D12,MASTER[Planned (Month) Bucket],"APRIL 26 PLANNED") -> 47 | BK12: =COUNTIFS(MASTER[ZH],$D12,MASTER[Planned (Month) Bucket],"APRIL 26 PLANNED",MASTER[Actual (Month) Bucket],"APRIL 26")+COUNTIFS(MASTER[ZH],$D12,MASTER[Planned (Month) Bucket],"MARCH 26 PLANNED",MASTER[Actual (Month) Bucket],"APRIL 26")+COUNTIFS(MASTER[ZH],$D12,MASTER[Planned (Month) Bucket],"FEBRUARY 26 PLANNED",MASTER[Actual (Month) Bucket],"APRIL 26")+COUNTIFS(MASTER[ZH],$D12,MASTER[Planned (Month) Bucket],"JANUARY 26 PLANNED",MASTER[Actual (Month) Bucket],"APRIL 26")+COUNTIFS(MASTER[ZH],$D12,MASTER[Planned (Month) Bucket],"MAY 26 PLANNED",MASTER[Actual (Month) Bucket],"APRIL 26") -> 11 | BL12: =COUNTIFS(MASTER[EPC Status (Current Week)],BL$4,MASTER[ZH],$D12,MASTER[Planned (Month) Bucket],"APRIL 26 PLANNED") -> 23 | BM12: =COUNTIFS(MASTER[EPC Status (Current Week)],BM$4,MASTER[ZH],$D12,MASTER[Planned (Month) Bucket],"APRIL 26 PLANNED") -> 0 | BN12: =BK12 -> 11 | BP12: =COUNTIFS(MASTER[ZH],$D12,MASTER[Planned (Month) Bucket],"MAY 26 PLANNED") -> 19 | BQ12: =COUNTIFS(MASTER[ZH],$D12,MASTER[Planned (Month) Bucket],"NOVEMBER 25 PLANNED",MASTER[Actual (Month) Bucket],"MAY 26")+COUNTIFS(MASTER[ZH],$D12,MASTER[Planned (Month) Bucket],"DECEMBER 25 PLANNED",MASTER[Actual (Month) Bucket],"MAY 26")+COUNTIFS(MASTER[ZH],$D12,MASTER[Planned (Month) Bucket],"FEBRUARY 26 PLANNED",MASTER[Actual (Month) Bucket],"MAY 26")+COUNTIFS(MASTER[ZH],$D12,MASTER[Planned (Month) Bucket],"MARCH 26 PLANNED",MASTER[Actual (Month) Bucket],"MAY 26")+COUNTIFS(MASTER[ZH],$D12,MASTER[Planned (Month) Bucket],"APRIL 26 PLANNED",MASTER[Actual (Month) Bucket],"MAY 26")+COUNTIFS(MASTER[ZH],$D12,MASTER[Planned (Month) Bucket],"MAY 26 PLANNED",MASTER[Actual (Month) Bucket],"MAY 26") -> 45 | BR12: =COUNTIFS(MASTER[EPC Status (Current Week)],BR$4,MASTER[ZH],$D12,MASTER[Planned (Month) Bucket],"MAY 26 PLANNED") -> 5 | BS12: =COUNTIFS(MASTER[EPC Status (Current Week)],BS$4,MASTER[ZH],$D12,MASTER[Planned (Month) Bucket],"MAY 26 PLANNED") -> 0 | BT12: =BQ12 -> 45 | BV12: =COUNTIFS(MASTER[ZH],$D12,MASTER[Planned (Month) Bucket],"JUNE 26 PLANNED") -> 8 | BW12: =COUNTIFS(MASTER[ZH],$D12,MASTER[Planned (Month) Bucket],"JUNE 26 PLANNED",MASTER[Actual (Month) Bucket],"JUNE 26")+COUNTIFS(MASTER[ZH],$D12,MASTER[Planned (Month) Bucket],"MAY 26 PLANNED",MASTER[Actual (Month) Bucket],"JUNE 26")+COUNTIFS(MASTER[ZH],$D12,MASTER[Planned (Month) Bucket],"APRIL 26 PLANNED",MASTER[Actual (Month) Bucket],"JUNE 26")+COUNTIFS(MASTER[ZH],$D12,MASTER[Planned (Month) Bucket],"MARCH 26 PLANNED",MASTER[Actual (Month) Bucket],"JUNE 26")+COUNTIFS(MASTER[ZH],$D12,MASTER[Planned (Month) Bucket],"FEBRUARY 26 PLANNED",MASTER[Actual (Month) Bucket],"JUNE 26") -> 2 | BX12: =COUNTIFS(MASTER[EPC Status (Current Week)],BX$4,MASTER[ZH],$D12,MASTER[Planned (Month) Bucket],"JUNE 26 PLANNED") -> 7 | BY12: =COUNTIFS(MASTER[EPC Status (Current Week)],BY$4,MASTER[ZH],$D12,MASTER[Planned (Month) Bucket],"JUNE 26 PLANNED") -> 1 | BZ12: =BW12 -> 2 | CB12: =COUNTIFS(MASTER[ZH],$D12,MASTER[Planned (Month) Bucket],"JULY 26 PLANNED") -> 4 | CC12: =COUNTIFS(MASTER[ZH],$D12,MASTER[Planned (Month) Bucket],"JULY 26 PLANNED",MASTER[Actual (Month) Bucket],"JULY 26") -> 0 | CD12: =COUNTIFS(MASTER[EPC Status (Current Week)],CD$4,MASTER[ZH],$D12,MASTER[Planned (Month) Bucket],"JULY 26 PLANNED") -> 3 | CE12: =COUNTIFS(MASTER[EPC Status (Current Week)],CE$4,MASTER[ZH],$D12,MASTER[Planned (Month) Bucket],"JULY 26 PLANNED") -> 1 | CF12: =CC12 -> 0 | CH12: =COUNTIFS(MASTER[ZH],$D12,MASTER[Planned (Month) Bucket],"AUGUST 26 PLANNED") -> 1 | CI12: =COUNTIFS(MASTER[ZH],$D12,MASTER[Planned (Month) Bucket],"AUGUST 26 PLANNED",MASTER[Actual (Month) Bucket],"AUG 26") -> 0 | CJ12: =COUNTIFS(MASTER[EPC Status (Current Week)],CJ$4,MASTER[ZH],$D12,MASTER[Planned (Month) Bucket],"AUGUST 26 PLANNED") -> 1 | CK12: =COUNTIFS(MASTER[EPC Status (Current Week)],CK$4,MASTER[ZH],$D12,MASTER[Planned (Month) Bucket],"AUGUST 26 PLANNED") -> 0 | CL12: =CI12 -> 0
